Workbook
Name valuevx: 42.314159
Name vertex42_copyright: "© 2011-2014 Vertex42 LLC"
Name vertex42_id: "work-order-template.xlsx"
Name vertex42_title: "Work Order Form Template"

Sheet Job_Order
K1: Form 1/3
J2: JOB ORDER NO.
B4: Hontech Auto Center
B5: 70 Bayan Bayanan Ave cor Narra St. | J5: DATE:
B6: Marikina Heights, Marikina City
B7: fb.com/hontechautocenter
B8: 85644550/ 71219124/ 09458757441/ 09525065084- VIBER
B9: CUSTOMER DETAILS
B10: Name : | G10: Year/Model : | J10: Plate No :
B11: Address : | G11: KM Reading : | J11: Intake Date :
B12: Contact No. : | G12: Engine No : | J12: Promise Date :
B13: E-Mail Add. : | G13: Chassis No. : | J13: Color :
B16: CUSTOMER'S DESCRIPTION OF REQUESTED SERVICE/CONCERN (To be filled out by Service Advisor)
B18: NOTE: To avail of the warranty given for material, parts, and service, owner supplied is discouraged, otherwise a surcharge of 25% of the price of item is automatically applied. The cost of the item/s shall be the current price of Hontech Auto Center, Inc.
B19: Interviewed by:
C20: Service Advisor
B21: AUTHORIZATION
B22: I hereby authorize you and your assigned employees to operate the vehicle for purposes of testing, inspection, pick-up or delivery.
D23: =C10
D24: Customer Name and Signature
B25: DIAGNOSTIC RESULT | D25: PARTS | H25: MATERIALS
D26: DESCRIPTION | E26: QTY | F26: UNIT PRICE | G26: AMOUNT | H26: DESCRIPTION | I26: QTY | J26: UNIT PRICE | K26: AMOUNT
G27: =E27*F27 -> 0 | K27: =I27*J27 -> 0
G28: =E28*F28 -> 0 | K28: =I28*J28 -> 0
G29: =E29*F29 -> 0 | K29: =I29*J29 -> 0
G30: =E30*F30 -> 0 | K30: =I30*J30 -> 0
G31: =E31*F31 -> 0 | K31: =I31*J31 -> 0
G32: =E32*F32 -> 0 | K32: =I32*J32 -> 0
G33: =E33*F33 -> 0 | K33: =I33*J33 -> 0
G34: =E34*F34 -> 0 | K34: =I34*J34 -> 0
G35: =E35*F35 -> 0 | K35: =I35*J35 -> 0
G36: =E36*F36 -> 0 | K36: =I36*J36 -> 0
G37: =E37*F37 -> 0 | K37: =I37*J37 -> 0
G38: =E38*F38 -> 0 | K38: =I38*J38 -> 0
... G49: =E49*F49 -> 0 | K49: =I49*J49 -> 0
F50: PARTS: | G50: =SUM(G27:G49) -> 0 | J50: MATERIALS: | K50: =SUM(K27:K49) -> 0
J51: TOTAL
B53: Diagnosed by: | H53: Assessed by:
C54: Auto Mechanic | I54: Parts/Materials Controller
B55: CERTIFICATE OF COMPLETION/ACCEPTANCE
...

Sheet Quotation_No 1
H1: Form 2/3
G2: QUOTATION NO.
A3: "Building Trust"
A4: Hontech Auto Center
A5: 70 Bayan Bayanan Ave cor Narra St. | G5: DATE:
A6: Marikina Heights, Marikina City | G6: JOB ORDER NO.: | H6: =Job_Order!K2
A7: fb.com/hontechautocenter | G7: PROMISED DATE:
A8: =Job_Order!B8 -> 85644550/ 71219124/ 09458757441/ 09525065084- VIBER
A9: CUSTOMER DETAILS
A10: Name: | B10: =Job_Order!C10 | F10: Plate No: | G10: =Job_Order!K10
A11: Address: | B11: =Job_Order!C11 | F11: Year/Model: | G11: =Job_Order!H10
A12: Contact No: | B12: =Job_Order!C12 | F12: Color: | G12: =Job_Order!K13
A14: PARTS/MATERIAL | C14: QTY | D14: FRT | E14: LABOR | F14: PARTS | G14: MATERALS | H14: AMOUNT
E15: =D15*550 -> 0 | H15: =E15+F15+G15 -> 0
E16: =D16*550 -> 0 | H16: =E16+F16+G16 -> 0
E17: =D17*550 -> 0 | H17: =E17+F17+G17 -> 0
E18: =D18*550 -> 0 | H18: =E18+F18+G18 -> 0
E19: =D19*550 -> 0 | H19: =E19+F19+G19 -> 0
E20: =D20*550 -> 0 | H20: =E20+F20+G20 -> 0
E21: =D21*550 -> 0 | H21: =E21+F21+G21 -> 0
E22: =D22*550 -> 0 | H22: =E22+F22+G22 -> 0
E23: =D23*550 -> 0 | H23: =E23+F23+G23 -> 0
E24: =D24*550 -> 0 | H24: =E24+F24+G24 -> 0
E25: =D25*550 -> 0 | H25: =E25+F25+G25 -> 0
E26: =D26*550 -> 0 | H26: =E26+F26+G26 -> 0
... E44: =D44*550 -> 0 | H44: =E44+F44+G44 -> 0
G45: LABOR | H45: =SUM(E15:E44) -> 0
G46: VAT 12% | H46: =(H45*12%) -> 0
G47: MATERIALS | H47: =SUM(G15:G44) -> 0
G48: PARTS | H48: =SUM(F15:F44) -> 0
G49: TOTAL | H49: =SUM(H45:H48) -> 0
A54: TERMS & CONDITIONS
A55: 1. This quotation is valid only for 15 days from the date of issuance.
A56: 2.The details of the estimate provided above are based on our first inspection and do not constitute a guarantee that no further work/parts will be required. The total bill of work will be per the details available on completion of work. Other terms and conditions as applicable.
A58: 3. Under certain circumstances, Hontech shall not be responsible for any loss or damage to the vehicle including article/s left therein while it is in the premise. Failure to claim your vehicle within the prescribed period shall bear a corresponding storage fee.
A59: 4. To avail of the warranty given for material, parts, and service, owner supplied is discouraged, otherwise a surcharge of 25% of the price of item/s is automatically applied. The price of the item/s shall be the current price of Hontech Auto Center, Inc.
A61: Prepared by: | F61: Approved by:
A63: SERVICE ADVISOR | F63: GENERAL MANAGER / AUTHORIZED OFFICER
A64: I hereby authorize the above repair work listed in accordance with our agreed discussion or with my authorized representative.
C65: =B10
...

Sheet Quotation_No 2
H1: Form 2/3
G2: QUOTATION NO.
A3: "Building Trust"
A4: Hontech Auto Center
A5: 70 Bayan Bayanan Ave cor Narra St. | G5: DATE:
A6: Marikina Heights, Marikina City | G6: JOB ORDER NO.: | H6: =Job_Order!K2
A7: fb.com/hontechautocenter | G7: PROMISED DATE:
A8: =Job_Order!B8 -> 85644550/ 71219124/ 09458757441/ 09525065084- VIBER
A9: CUSTOMER DETAILS
A10: Name: | B10: =Job_Order!C10 | F10: Plate No: | G10: =Job_Order!K10
A11: Address: | B11: =Job_Order!C11 | F11: Year/Model: | G11: =Job_Order!H10
A12: Contact No: | B12: =Job_Order!C12 | F12: Color: | G12: =Job_Order!K13
A14: PARTS/MATERIAL | C14: QTY | D14: FRT | E14: LABOR | F14: PARTS | G14: MATERALS | H14: AMOUNT
E15: =D15*550 -> 0 | H15: =E15+F15+G15 -> 0
E16: =D16*550 -> 0 | H16: =E16+F16+G16 -> 0
E17: =D17*550 -> 0 | H17: =E17+F17+G17 -> 0
E18: =D18*550 -> 0 | H18: =E18+F18+G18 -> 0
E19: =D19*550 -> 0 | H19: =E19+F19+G19 -> 0
E20: =D20*550 -> 0 | H20: =E20+F20+G20 -> 0
E21: =D21*550 -> 0 | H21: =E21+F21+G21 -> 0
E22: =D22*550 -> 0 | H22: =E22+F22+G22 -> 0
E23: =D23*550 -> 0 | H23: =E23+F23+G23 -> 0
E24: =D24*550 -> 0 | H24: =E24+F24+G24 -> 0
E25: =D25*550 -> 0 | H25: =E25+F25+G25 -> 0
E26: =D26*550 -> 0 | H26: =E26+F26+G26 -> 0
... E44: =D44*550 -> 0 | H44: =E44+F44+G44 -> 0
G45: LABOR | H45: =SUM(E15:E44) -> 0
G46: VAT 12% | H46: =(H45*12%) -> 0
G47: MATERIALS | H47: =SUM(G15:G44) -> 0
G48: PARTS | H48: =SUM(F15:F44) -> 0
G49: TOTAL | H49: =SUM(H45:H48) -> 0
A54: TERMS & CONDITIONS
A55: 1. This quotation is valid only for 15 days from the date of issuance.
A56: 2.The details of the estimate provided above are based on our first inspection and do not constitute a guarantee that no further work/parts will be required. The total bill of work will be per the details available on completion of work. Other terms and conditions as applicable.
A58: 3. Under certain circumstances, Hontech shall not be responsible for any loss or damage to the vehicle including article/s left therein while it is in the premise. Failure to claim your vehicle within the prescribed period shall bear a corresponding storage fee.
A59: 4. To avail of the warranty given for material, parts, and service, owner supplied is discouraged, otherwise a surcharge of 25% of the price of item/s is automatically applied. The price of the item/s shall be the current price of Hontech Auto Center, Inc.
A61: Prepared by: | F61: Approved by:
A63: SERVICE ADVISOR | F63: GENERAL MANAGER / AUTHORIZED OFFICER
A64: I hereby authorize the above repair work listed in accordance with our agreed discussion or with my authorized representative.
C65: =B10
...

Sheet Quotation_No 3
H1: Form 2/3
G2: QUOTATION NO.
A3: "Building Trust"
A4: Hontech Auto Center
A5: 70 Bayan Bayanan Ave cor Narra St. | G5: DATE:
A6: Marikina Heights, Marikina City | G6: JOB ORDER NO.: | H6: =Job_Order!K2
A7: fb.com/hontechautocenter | G7: PROMISED DATE:
A8: =Job_Order!B8 -> 85644550/ 71219124/ 09458757441/ 09525065084- VIBER
A9: CUSTOMER DETAILS
A10: Name: | B10: =Job_Order!C10 | F10: Plate No: | G10: =Job_Order!K10
A11: Address: | B11: =Job_Order!C11 | F11: Year/Model: | G11: =Job_Order!H10
A12: Contact No: | B12: =Job_Order!C12 | F12: Color: | G12: =Job_Order!K13
A14: PARTS/MATERIAL | C14: QTY | D14: FRT | E14: LABOR | F14: PARTS | G14: MATERALS | H14: AMOUNT
E15: =D15*550 -> 0 | H15: =E15+F15+G15 -> 0
E16: =D16*550 -> 0 | H16: =E16+F16+G16 -> 0
E17: =D17*550 -> 0 | H17: =E17+F17+G17 -> 0
E18: =D18*550 -> 0 | H18: =E18+F18+G18 -> 0
E19: =D19*550 -> 0 | H19: =E19+F19+G19 -> 0
E20: =D20*550 -> 0 | H20: =E20+F20+G20 -> 0
E21: =D21*550 -> 0 | H21: =E21+F21+G21 -> 0
E22: =D22*550 -> 0 | H22: =E22+F22+G22 -> 0
E23: =D23*550 -> 0 | H23: =E23+F23+G23 -> 0
E24: =D24*550 -> 0 | H24: =E24+F24+G24 -> 0
E25: =D25*550 -> 0 | H25: =E25+F25+G25 -> 0
E26: =D26*550 -> 0 | H26: =E26+F26+G26 -> 0
... E44: =D44*550 -> 0 | H44: =E44+F44+G44 -> 0
G45: LABOR | H45: =SUM(E15:E44) -> 0
G46: VAT 12% | H46: =(H45*12%) -> 0
G47: MATERIALS | H47: =SUM(G15:G44) -> 0
G48: PARTS | H48: =SUM(F15:F44) -> 0
G49: TOTAL | H49: =SUM(H45:H48) -> 0
A54: TERMS & CONDITIONS
A55: 1. This quotation is valid only for 15 days from the date of issuance.
A56: 2.The details of the estimate provided above are based on our first inspection and do not constitute a guarantee that no further work/parts will be required. The total bill of work will be per the details available on completion of work. Other terms and conditions as applicable.
A58: 3. Under certain circumstances, Hontech shall not be responsible for any loss or damage to the vehicle including article/s left therein while it is in the premise. Failure to claim your vehicle within the prescribed period shall bear a corresponding storage fee.
A59: 4. To avail of the warranty given for material, parts, and service, owner supplied is discouraged, otherwise a surcharge of 25% of the price of item/s is automatically applied. The price of the item/s shall be the current price of Hontech Auto Center, Inc.
A61: Prepared by: | F61: Approved by:
A63: SERVICE ADVISOR | F63: GENERAL MANAGER / AUTHORIZED OFFICER
A64: I hereby authorize the above repair work listed in accordance with our agreed discussion or with my authorized representative.
C65: =B10
...

Sheet Billing_No 1
H1: Form 3/3
G2: BILLING NO.
A3: "Building Trust"
A4: Hontech Auto Center
A5: 70 Bayan Bayanan Ave cor Narra St. | G5: DATE:
A6: Marikina Heights, Marikina City | G6: JOB ORDER NO.: | H6: =Job_Order!K2
A7: fb.com/hontechautocenter | G7: QUOTATION NO.: | H7: ='Quotation_No 1'!H2
A8: =Job_Order!B8 -> 85644550/ 71219124/ 09458757441/ 09525065084- VIBER
A9: CUSTOMER DETAILS
A10: Name : | B10: =Job_Order!C10 | F10: Plate No: | G10: =Job_Order!K10
A11: Address : | B11: =Job_Order!C11 | F11: Model/Year: | G11: =Job_Order!H10
A12: Contact No: | B12: =Job_Order!C12 | F12: Color: | G12: =Job_Order!K13
A13: E-Mail Add : | B13: =Job_Order!C13 | F13: Km Reading: | G13: =Job_Order!H11
A14: This is to bill you in the amount of | C14: =H57 -> 0 | D14: with the following details described below:
A16: PARTS/MATERIAL | C16: QTY | D16: FRT | E16: LABOR | F16: PARTS | G16: MATERALS | H16: AMOUNT
E17: =D17*550 -> 0 | H17: =G17+F17+E17 -> 0
E18: =D18*550 -> 0 | H18: =E18+F18+G18 -> 0
E19: =D19*550 -> 0 | H19: =E19+F19+G19 -> 0
E20: =D20*550 -> 0 | H20: =E20+F20+G20 -> 0
E21: =D21*550 -> 0 | H21: =E21+F21+G21 -> 0
E22: =D22*550 -> 0 | H22: =E22+F22+G22 -> 0
E23: =D23*550 -> 0 | H23: =E23+F23+G23 -> 0
E24: =D24*550 -> 0 | H24: =E24+F24+G24 -> 0
E25: =D25*550 -> 0 | H25: =E25+F25+G25 -> 0
E26: =D26*550 -> 0 | H26: =E26+F26+G26 -> 0
E27: =D27*550 -> 0 | H27: =E27+F27+G27 -> 0
E28: =D28*550 -> 0 | H28: =E28+F28+G28 -> 0
E29: =D29*550 -> 0 | H29: =E29+F29+G29 -> 0
... E52: =D52*550 -> 0 | H52: =E52+F52+G52 -> 0
G53: LABOR | H53: =SUM(E17:E52) -> 0
A54: TERMS & CONDITIONS | G54: VAT 12% | H54: =(H53*12%) -> 0
A55: Failure to claim vehicle within the prescribed period shall bear a corresponding storage fee. Replaced items/parts/materials from the vehicle within 30 days shall be disposed of without prior notice. | G55: MATERIALS | H55: =SUM(G17:G52) -> 0
G56: PARTS | H56: =SUM(F17:F52) -> 0
G57: TOTAL | H57: =SUM(H53:H56) -> 0
A58: HONTECH MANGEMENT:
A60: Service Advisor
A62: Thank you for trusting us!

Sheet Billing_No 2
H1: Form 3/3
G2: BILLING NO.
A3: "Building Trust"
A4: Hontech Auto Center
A5: 70 Bayan Bayanan Ave cor Narra St. | G5: DATE:
A6: Marikina Heights, Marikina City | G6: JOB ORDER NO.: | H6: =Job_Order!K2
A7: fb.com/hontechautocenter | G7: QUOTATION NO.: | H7: ='Quotation_No 1'!H2
A8: =Job_Order!B8 -> 85644550/ 71219124/ 09458757441/ 09525065084- VIBER
A9: CUSTOMER DETAILS
A10: Name : | B10: =Job_Order!C10 | F10: Plate No: | G10: =Job_Order!K10
A11: Address : | B11: =Job_Order!C11 | F11: Model/Year: | G11: =Job_Order!H10
A12: Contact No: | B12: =Job_Order!C12 | F12: Color: | G12: =Job_Order!K13
A13: E-Mail Add : | B13: =Job_Order!C13 | F13: Km Reading: | G13: =Job_Order!H11
A14: This is to bill you in the amount of | C14: =H57 -> 0 | D14: with the following details described below:
A16: PARTS/MATERIAL | C16: QTY | D16: FRT | E16: LABOR | F16: PARTS | G16: MATERALS | H16: AMOUNT
E17: =D17*550 -> 0 | H17: =G17+F17+E17 -> 0
E18: =D18*550 -> 0 | H18: =E18+F18+G18 -> 0
E19: =D19*550 -> 0 | H19: =E19+F19+G19 -> 0
E20: =D20*550 -> 0 | H20: =E20+F20+G20 -> 0
E21: =D21*550 -> 0 | H21: =E21+F21+G21 -> 0
E22: =D22*550 -> 0 | H22: =E22+F22+G22 -> 0
E23: =D23*550 -> 0 | H23: =E23+F23+G23 -> 0
E24: =D24*550 -> 0 | H24: =E24+F24+G24 -> 0
E25: =D25*550 -> 0 | H25: =E25+F25+G25 -> 0
E26: =D26*550 -> 0 | H26: =E26+F26+G26 -> 0
E27: =D27*550 -> 0 | H27: =E27+F27+G27 -> 0
E28: =D28*550 -> 0 | H28: =E28+F28+G28 -> 0
E29: =D29*550 -> 0 | H29: =E29+F29+G29 -> 0
... E52: =D52*550 -> 0 | H52: =E52+F52+G52 -> 0
G53: LABOR | H53: =SUM(E17:E52) -> 0
A54: TERMS & CONDITIONS | G54: VAT 12% | H54: =(H53*12%) -> 0
A55: Failure to claim vehicle within the prescribed period shall bear a corresponding storage fee. Replaced items/parts/materials from the vehicle within 30 days shall be disposed of without prior notice. | G55: MATERIALS | H55: =SUM(G17:G52) -> 0
G56: PARTS | H56: =SUM(F17:F52) -> 0
G57: TOTAL | H57: =SUM(H53:H56) -> 0
A58: HONTECH MANGEMENT:
A60: Service Advisor
A62: Thank you for trusting us!

Sheet CheckList_Result
A5: CUSTOMER NAME | C5: =Job_Order!C10 | L5: DATE | M5: =Job_Order!K5
A6: PLATE NUMBER | C6: =Job_Order!K10 | F6: CHECKLIST RESULT
A7: VEHICLE YEAR MODEL | D7: =Job_Order!H10
D61: 0 | H61: =Job_Order!C10
B62: TECHNICIAN NAME____________________ | I62: CUSTOMER SIGNATURE
