Workbook

Sheet Summary
A1: HonTech QA Checklist Summary
A2: Counts update automatically from the QA Checklist sheet.
A4: Overall | B4: Count
A5: Total tests | B5: =COUNTA('QA Checklist'!$A$5:$A$174)
A6: Passed | B6: =COUNTIF('QA Checklist'!$H$5:$H$174,"Passed")+COUNTIF('QA Checklist'!$H$5:$H$174,"Pass")
A7: Failed | B7: =COUNTIF('QA Checklist'!$H$5:$H$174,"Failed")+COUNTIF('QA Checklist'!$H$5:$H$174,"Fail")
A8: Pending | B8: =COUNTIF('QA Checklist'!$H$5:$H$174,"Pending")
A9: Pass rate (Passed / Total) | B9: =IF(B5=0,0,B6/B5)
A11: By area | B11: Total | C11: Passed | D11: Failed | E11: Pending | F11: % Passed
A12: AI Workflow | B12: =COUNTIF('QA Checklist'!$B$5:$B$174,$A12) | C12: =COUNTIFS('QA Checklist'!$B$5:$B$174,$A12,'QA Checklist'!$H$5:$H$174,"Passed")+COUNTIFS('QA Checklist'!$B$5:$B$174,$A12,'QA Checklist'!$H$5:$H$174,"Pass") | D12: =COUNTIFS('QA Checklist'!$B$5:$B$174,$A12,'QA Checklist'!$H$5:$H$174,"Failed")+COUNTIFS('QA Checklist'!$B$5:$B$174,$A12,'QA Checklist'!$H$5:$H$174,"Fail") | E12: =COUNTIFS('QA Checklist'!$B$5:$B$174,$A12,'QA Checklist'!$H$5:$H$174,"Pending") | F12: =IF(B12=0,0,C12/B12)
A13: Assistant Staff | B13: =COUNTIF('QA Checklist'!$B$5:$B$174,$A13) | C13: =COUNTIFS('QA Checklist'!$B$5:$B$174,$A13,'QA Checklist'!$H$5:$H$174,"Passed")+COUNTIFS('QA Checklist'!$B$5:$B$174,$A13,'QA Checklist'!$H$5:$H$174,"Pass") | D13: =COUNTIFS('QA Checklist'!$B$5:$B$174,$A13,'QA Checklist'!$H$5:$H$174,"Failed")+COUNTIFS('QA Checklist'!$B$5:$B$174,$A13,'QA Checklist'!$H$5:$H$174,"Fail") | E13: =COUNTIFS('QA Checklist'!$B$5:$B$174,$A13,'QA Checklist'!$H$5:$H$174,"Pending") | F13: =IF(B13=0,0,C13/B13)
A14: Authentication | B14: =COUNTIF('QA Checklist'!$B$5:$B$174,$A14) | C14: =COUNTIFS('QA Checklist'!$B$5:$B$174,$A14,'QA Checklist'!$H$5:$H$174,"Passed")+COUNTIFS('QA Checklist'!$B$5:$B$174,$A14,'QA Checklist'!$H$5:$H$174,"Pass") | D14: =COUNTIFS('QA Checklist'!$B$5:$B$174,$A14,'QA Checklist'!$H$5:$H$174,"Failed")+COUNTIFS('QA Checklist'!$B$5:$B$174,$A14,'QA Checklist'!$H$5:$H$174,"Fail") | E14: =COUNTIFS('QA Checklist'!$B$5:$B$174,$A14,'QA Checklist'!$H$5:$H$174,"Pending") | F14: =IF(B14=0,0,C14/B14)
A15: Developer Tooling | B15: =COUNTIF('QA Checklist'!$B$5:$B$174,$A15) | C15: =COUNTIFS('QA Checklist'!$B$5:$B$174,$A15,'QA Checklist'!$H$5:$H$174,"Passed")+COUNTIFS('QA Checklist'!$B$5:$B$174,$A15,'QA Checklist'!$H$5:$H$174,"Pass") | D15: =COUNTIFS('QA Checklist'!$B$5:$B$174,$A15,'QA Checklist'!$H$5:$H$174,"Failed")+COUNTIFS('QA Checklist'!$B$5:$B$174,$A15,'QA Checklist'!$H$5:$H$174,"Fail") | E15: =COUNTIFS('QA Checklist'!$B$5:$B$174,$A15,'QA Checklist'!$H$5:$H$174,"Pending") | F15: =IF(B15=0,0,C15/B15)
A16: Diagnostics | B16: =COUNTIF('QA Checklist'!$B$5:$B$174,$A16) | C16: =COUNTIFS('QA Checklist'!$B$5:$B$174,$A16,'QA Checklist'!$H$5:$H$174,"Passed")+COUNTIFS('QA Checklist'!$B$5:$B$174,$A16,'QA Checklist'!$H$5:$H$174,"Pass") | D16: =COUNTIFS('QA Checklist'!$B$5:$B$174,$A16,'QA Checklist'!$H$5:$H$174,"Failed")+COUNTIFS('QA Checklist'!$B$5:$B$174,$A16,'QA Checklist'!$H$5:$H$174,"Fail") | E16: =COUNTIFS('QA Checklist'!$B$5:$B$174,$A16,'QA Checklist'!$H$5:$H$174,"Pending") | F16: =IF(B16=0,0,C16/B16)
A17: Owner / Analytics | B17: =COUNTIF('QA Checklist'!$B$5:$B$174,$A17) | C17: =COUNTIFS('QA Checklist'!$B$5:$B$174,$A17,'QA Checklist'!$H$5:$H$174,"Passed")+COUNTIFS('QA Checklist'!$B$5:$B$174,$A17,'QA Checklist'!$H$5:$H$174,"Pass") | D17: =COUNTIFS('QA Checklist'!$B$5:$B$174,$A17,'QA Checklist'!$H$5:$H$174,"Failed")+COUNTIFS('QA Checklist'!$B$5:$B$174,$A17,'QA Checklist'!$H$5:$H$174,"Fail") | E17: =COUNTIFS('QA Checklist'!$B$5:$B$174,$A17,'QA Checklist'!$H$5:$H$174,"Pending") | F17: =IF(B17=0,0,C17/B17)
A18: SA 2025 RO Studio | B18: =COUNTIF('QA Checklist'!$B$5:$B$174,$A18) | C18: =COUNTIFS('QA Checklist'!$B$5:$B$174,$A18,'QA Checklist'!$H$5:$H$174,"Passed")+COUNTIFS('QA Checklist'!$B$5:$B$174,$A18,'QA Checklist'!$H$5:$H$174,"Pass") | D18: =COUNTIFS('QA Checklist'!$B$5:$B$174,$A18,'QA Checklist'!$H$5:$H$174,"Failed")+COUNTIFS('QA Checklist'!$B$5:$B$174,$A18,'QA Checklist'!$H$5:$H$174,"Fail") | E18: =COUNTIFS('QA Checklist'!$B$5:$B$174,$A18,'QA Checklist'!$H$5:$H$174,"Pending") | F18: =IF(B18=0,0,C18/B18)
A19: Security & RBAC | B19: =COUNTIF('QA Checklist'!$B$5:$B$174,$A19) | C19: =COUNTIFS('QA Checklist'!$B$5:$B$174,$A19,'QA Checklist'!$H$5:$H$174,"Passed")+COUNTIFS('QA Checklist'!$B$5:$B$174,$A19,'QA Checklist'!$H$5:$H$174,"Pass") | D19: =COUNTIFS('QA Checklist'!$B$5:$B$174,$A19,'QA Checklist'!$H$5:$H$174,"Failed")+COUNTIFS('QA Checklist'!$B$5:$B$174,$A19,'QA Checklist'!$H$5:$H$174,"Fail") | E19: =COUNTIFS('QA Checklist'!$B$5:$B$174,$A19,'QA Checklist'!$H$5:$H$174,"Pending") | F19: =IF(B19=0,0,C19/B19)
A20: Service Advisor | B20: =COUNTIF('QA Checklist'!$B$5:$B$174,$A20) | C20: =COUNTIFS('QA Checklist'!$B$5:$B$174,$A20,'QA Checklist'!$H$5:$H$174,"Passed")+COUNTIFS('QA Checklist'!$B$5:$B$174,$A20,'QA Checklist'!$H$5:$H$174,"Pass") | D20: =COUNTIFS('QA Checklist'!$B$5:$B$174,$A20,'QA Checklist'!$H$5:$H$174,"Failed")+COUNTIFS('QA Checklist'!$B$5:$B$174,$A20,'QA Checklist'!$H$5:$H$174,"Fail") | E20: =COUNTIFS('QA Checklist'!$B$5:$B$174,$A20,'QA Checklist'!$H$5:$H$174,"Pending") | F20: =IF(B20=0,0,C20/B20)
A21: Staff Access | B21: =COUNTIF('QA Checklist'!$B$5:$B$174,$A21) | C21: =COUNTIFS('QA Checklist'!$B$5:$B$174,$A21,'QA Checklist'!$H$5:$H$174,"Passed")+COUNTIFS('QA Checklist'!$B$5:$B$174,$A21,'QA Checklist'!$H$5:$H$174,"Pass") | D21: =COUNTIFS('QA Checklist'!$B$5:$B$174,$A21,'QA Checklist'!$H$5:$H$174,"Failed")+COUNTIFS('QA Checklist'!$B$5:$B$174,$A21,'QA Checklist'!$H$5:$H$174,"Fail") | E21: =COUNTIFS('QA Checklist'!$B$5:$B$174,$A21,'QA Checklist'!$H$5:$H$174,"Pending") | F21: =IF(B21=0,0,C21/B21)
A22: TV Monitor | B22: =COUNTIF('QA Checklist'!$B$5:$B$174,$A22) | C22: =COUNTIFS('QA Checklist'!$B$5:$B$174,$A22,'QA Checklist'!$H$5:$H$174,"Passed")+COUNTIFS('QA Checklist'!$B$5:$B$174,$A22,'QA Checklist'!$H$5:$H$174,"Pass") | D22: =COUNTIFS('QA Checklist'!$B$5:$B$174,$A22,'QA Checklist'!$H$5:$H$174,"Failed")+COUNTIFS('QA Checklist'!$B$5:$B$174,$A22,'QA Checklist'!$H$5:$H$174,"Fail") | E22: =COUNTIFS('QA Checklist'!$B$5:$B$174,$A22,'QA Checklist'!$H$5:$H$174,"Pending") | F22: =IF(B22=0,0,C22/B22)
A23: Total | B23: =SUM(B12:B22) | C23: =SUM(C12:C22) | D23: =SUM(D12:D22) | E23: =SUM(E12:E22) | F23: =IF(B23=0,0,C23/B23)
A25: By risk tier | B25: Total | C25: Passed | D25: Failed | E25: Pending
A26: Tier 1 | B26: =COUNTIF('QA Checklist'!$C$5:$C$174,$A26&"*") | C26: =COUNTIFS('QA Checklist'!$C$5:$C$174,$A26&"*",'QA Checklist'!$H$5:$H$174,"Passed")+COUNTIFS('QA Checklist'!$C$5:$C$174,$A26&"*",'QA Checklist'!$H$5:$H$174,"Pass") | D26: =COUNTIFS('QA Checklist'!$C$5:$C$174,$A26&"*",'QA Checklist'!$H$5:$H$174,"Failed")+COUNTIFS('QA Checklist'!$C$5:$C$174,$A26&"*",'QA Checklist'!$H$5:$H$174,"Fail") | E26: =COUNTIFS('QA Checklist'!$C$5:$C$174,$A26&"*",'QA Checklist'!$H$5:$H$174,"Pending")
A27: Tier 2 | B27: =COUNTIF('QA Checklist'!$C$5:$C$174,$A27&"*") | C27: =COUNTIFS('QA Checklist'!$C$5:$C$174,$A27&"*",'QA Checklist'!$H$5:$H$174,"Passed")+COUNTIFS('QA Checklist'!$C$5:$C$174,$A27&"*",'QA Checklist'!$H$5:$H$174,"Pass") | D27: =COUNTIFS('QA Checklist'!$C$5:$C$174,$A27&"*",'QA Checklist'!$H$5:$H$174,"Failed")+COUNTIFS('QA Checklist'!$C$5:$C$174,$A27&"*",'QA Checklist'!$H$5:$H$174,"Fail") | E27: =COUNTIFS('QA Checklist'!$C$5:$C$174,$A27&"*",'QA Checklist'!$H$5:$H$174,"Pending")
A28: Tier 3 | B28: =COUNTIF('QA Checklist'!$C$5:$C$174,$A28&"*") | C28: =COUNTIFS('QA Checklist'!$C$5:$C$174,$A28&"*",'QA Checklist'!$H$5:$H$174,"Passed")+COUNTIFS('QA Checklist'!$C$5:$C$174,$A28&"*",'QA Checklist'!$H$5:$H$174,"Pass") | D28: =COUNTIFS('QA Checklist'!$C$5:$C$174,$A28&"*",'QA Checklist'!$H$5:$H$174,"Failed")+COUNTIFS('QA Checklist'!$C$5:$C$174,$A28&"*",'QA Checklist'!$H$5:$H$174,"Fail") | E28: =COUNTIFS('QA Checklist'!$C$5:$C$174,$A28&"*",'QA Checklist'!$H$5:$H$174,"Pending")

Sheet QA Checklist
A1: HonTech QA Test Checklist
A2: Source: Hontech Documentation/HONTECH_QA_TEST_CHECKLIST.csv. Testers: set the Status column (dropdown: Pending / Passed / Failed) and write what you observed in Tester Notes. Use the filter arrows on row 4 to show one role, area or status. Yellow Test ID = ID used more than once.
A4: Test ID | B4: Area | C4: Risk Tier | D4: Module / Category | E4: Target Role | F4: Action Under Test | G4: Expected Behavior | H4: Status | I4: Tester Notes / Observed Behavior
A5: AUTH-01 | B5: Authentication | C5: Tier 3 (Shared Core) | D5: Authentication | E5: All Roles | F5: Login with Valid Credentials (owner@hontech.com / admin123) | G5: Authenticates and redirects to role dashboard without blank screen | H5: Pending
A6: AUTH-02 | B6: Authentication | C6: Tier 2 (Single-Role) | D6: Authentication | E6: All Roles | F6: Login with Invalid Password | G6: Displays clear error toast "Invalid email or password" without crash | H6: Pending
A7: AUTH-03 | B7: Authentication | C7: Tier 2 (Single-Role) | D7: Authentication | E7: All Roles | F7: Forgot Password PIN Verification | G7: Validates 4-digit security PIN and allows setting new password | H7: Pending
A8: AUTH-04 | B8: Authentication | C8: Tier 1 (Visual/Cosmetic) | D8: Authentication | E8: All Roles | F8: Quick-Copy Dev Credentials Badges | G8: Clicking credential badge auto-fills email and password inputs instantly | H8: Pending
A9: AUTH-05 | B9: Authentication | C9: Tier 3 (Shared Core) | D9: Authentication | E9: All Roles | F9: Session Presence Ping (Heartbeat) | G9: Background ping sends every 30s to keep user status online in database | H9: Pending
A10: AUTH-06 | B10: Authentication | C10: Tier 3 (Shared Core) | D10: Authentication | E10: All Roles | F10: Logout Flow | G10: Clears active JWT session and smoothly redirects back to login portal | H10: Pending
A11: AUTH-07 | B11: Authentication | C11: Tier 3 (Shared Core) | D11: Authentication | E11: Assistant Staff | F11: RBAC Route Protection Check | G11: Attempting to query /api/auth/staff returns 403 Forbidden | H11: Pending
A12: OWN-01 | B12: Owner / Analytics | C12: Tier 2 (Single-Role) | D12: Analytics Overview | E12: Owner | F12: KPI Metrics Calculation (Released Today, In Bays, Total) | G12: Cards calculate real totals from MySQL data and show subtext badges | H12: Pending
A13: OWN-02 | B13: Owner / Analytics | C13: Tier 2 (Single-Role) | D13: Analytics Overview | E13: Owner | F13: Volume Trends Line Chart Rendering | G13: Chart.js canvas renders daily vehicle throughput without script errors | H13: Pending
A14: OWN-03 | B14: Owner / Analytics | C14: Tier 1 (Visual/Cosmetic) | D14: Analytics Overview | E14: Owner | F14: Service Category Breakdown Doughnut Chart | G14: Renders PMS, GRS, PMS & GRS, Others proportions accurately | H14: Pending
A15: OWN-04 | B15: Owner / Analytics | C15: Tier 2 (Single-Role) | D15: Analytics Overview | E15: Owner | F15: Period Record Log Table Sub-Tab Access | G15: Sub-tab 3 displays historical and active operational records table | H15: Pending
A16: OWN-05 | B16: Owner / Analytics | C16: Tier 2 (Single-Role) | D16: Analytics Overview | E16: Owner | F16: Period Log Column Header Sorting (ASC/DESC) | G16: Clicking headers (Plate, Date, SLA) toggles sorting with arrow indicators | H16: Pending
... A109: SA-STU-42 | B109: SA 2025 RO Studio | C109: Tier 1 (Core Reliability & Data Integrity) | D109: 2025 RO Excel Studio | E109: Service Advisor | F109: Multi-Sheet Quotation (Sheets 2-4) & Billing (Sheets 5-6) Auto-Sync Export Mirroring | G109: When SA clicks [Export Official .xlsx] all 3 Quotation copies (Quotation_No 1-3) and both Billing copies (Billing_No 1-2) automatically populate with mirrored repair order items (Desc Qty FRT Labor Parts Materials Total Amount) across rows 15-44 (Quotation) and rows 17-52 (Billing); header dossier and authentic signatures populate across all sheets; dummy item initializers are purged preventing stale data shadowing | H109: Pending
A110: SA-STU-43 | B110: SA 2025 RO Studio | C110: Tier 1 (Core Reliability & Data Integrity) | D110: 2025 RO Excel Studio | E110: Service Advisor | F110: Live Studio Cross-Sheet Typing PDF Sync & Exact Coordinates 7-Sheet XLSX Export | G110: Typing in Job Order automatically cascades customer vehicle dossier and line items to Quotation and Billing with confirmed 0.00 labor default; right-column PDF format previews render live updates within 350ms across all sheets with green live sync badges; exact coordinates and plain text signatures align across Quotation Billing and Checklist; [Export Official .xlsx] injects natural data across all 7 sheets with OpenXML tamper protection | H110: Passed | I110: Verified by User 2026-09-21
A111: SA-STU-44 | B111: SA 2025 RO Studio | C111: Tier 1 (Core Reliability & Data Integrity) | D111: 2025 RO Excel Studio | E111: Service Advisor | F111: Hoisted Personnel Scoping in Multi-Sheet XLSX Export | G111: Clicking [Export Official .xlsx] successfully exports the full 7-sheet workbook without runtime ReferenceError: manager is not defined; ensures manager mechanic and assessor signatures properly populate across Job_Order and Quotation worksheets | H111: Passed | I111: Verified by User 2026-09-21
A112: SA-STU-45 | B112: SA 2025 RO Studio | C112: Tier 2 (Workflow & Ergonomics) | D112: 2025 RO Excel Studio (All Sheets) | E112: Service Advisor | F112: Follow-Along Sticky PDF Preview & Viewport Height Across All Sheets | G112: Scrolling down through lengthy form inputs (Customer Details Diagnostics Scope Parts/Materials Signatures) smoothly follows the right-side PDF preview using sticky top-14 self-start positioning with adaptive h-[calc(100vh-8.5rem)] container height across Job_Order Quotation_No Billing_No and CheckList_Result worksheets | H112: Pending
A113: SA-STU-46 | B113: SA 2025 RO Studio | C113: Tier 1 (Core Reliability & Data Integrity) | D113: 2025 RO Excel Studio (All Sheets) | E113: Service Advisor | F113: Authentic Excel Typography & Non-Bold Formatting Alignment in Live PDF Preview | G113: Renders customer dossier vehicle details line items subtotals and staff signatures in clean regular non-bold font matching Excel template cells (bold=False); preserves bold emphasis on Grand Totals and Row 14 banner for audit clarity across Job_Order Quotation_No Billing_No and CheckList_Result PDF previews | H113: Pending
A114: SA-STU-47 | B114: SA 2025 RO Studio | C114: Tier 1 (Core Reliability & Data Integrity) | D114: 2025 RO Excel Studio | E114: Service Advisor | F114: Migration to Current_2025 BLANK RO UPDATED_V1.xlsx Official Export Template | G114: When clicking [Export Official .xlsx] system loads pristine Current_2025 BLANK RO UPDATED_V1.xlsx; injects data across all 7 sheets; preserves Sheet 7 dynamic formulas (C2 AD2 C3 C4 M63) and applies OpenXML tamper protection | H114: Pending
A115: SA-STU-48 | B115: SA 2025 RO Studio | C115: Tier 1 (Core Reliability & Data Integrity) | D115: 2025 RO Excel Studio (CheckList_Result) | E115: Service Advisor | F115: Multi-Point Receiving Checklist Color Status Stamping & Studio Controls | G115: When SA marks inspection checkpoints as Good Attention or Defect in the Checklist Studio clicking [Export Official .xlsx] stamps centered checkmarks ✓ into the corresponding green (#2FB044) yellow (#FFED00) or red (#EE1C25) status indicator cells in Sheet 7; stamps selected fuel gauge in Row 4; injects SA technician name into C63 and comments into B53; provides rapid one-click [✓ All Good] and [Reset] studio batch buttons | H115: Passed | I115: Verified by Automated Unit Tests (AUT-FRONT-96)
A116: SA-STU-49 | B116: SA 2025 RO Studio | C116: Tier 1 (Core Reliability & Data Integrity) | D116: 2025 RO Excel Studio (CheckList_Result) | E116: Service Advisor | F116: Checklist Completeness & Color Box Stamping for Interior Light Hydraulic Clutch Drive Shaft & Brakes Not Inspected | G116: When SA marks interior lights (Row 11: I11/J11/K11) hydraulic clutch fluid (Row 44: I44/J44/K44) drive shaft boots (Row 50: I50/J50/K50) or toggles Brakes not inspected on this visit (Row 37: M37) exportOfficialXLSX accurately stamps checkmarks into each item's color status box and updates M37 with [✓] Brakes not inspected on this visit; also maps parking brake (Row 16) horn operation (Row 18) clutch operation (Row 20) air filter (Row 40) and fluid leaks (Row 49) | H116: Passed | I116: Verified by Automated Unit Tests (AUT-FRONT-97)
A117: SA-STU-50 | B117: SA 2025 RO Studio | C117: Tier 1 (Core Reliability & Data Integrity) | D117: 2025 RO Excel Studio (Quotation_No & Billing_No) | E117: Service Advisor | F117: Quotation & Billing Form Table Alignment & Dynamic PDF Compiler Verification | G117: When SA opens Quotation_No or Billing_No Studio line items render seamlessly with 6-column matrix (# Description Qty Price Total Remove); typing numbers instantly re-sums subtotals VAT and grand total in summary cards; live PDF format previews recompile without runtime ReferenceErrors using drawTextCenter and localized whiteout masking over template 0.00 placeholders with exact coordinates | H117: Passed | I117: Verified by Automated Unit Tests (AUT-FRONT-98)
A118: SA-STU-51 | B118: SA 2025 RO Studio | C118: Tier 2 (Workflow & Ergonomics) | D118: 2025 RO Excel Studio (All Sheets) | E118: Service Advisor | F118: Senior SA Adaptive Auto-Magnifier & Real-Time Document Section Gliding | G118: When SA types into form inputs (Name Plate Scope Claim Stub) preview automatically glides and magnifies (185% zoom) directly over that specific section of the document with instantaneous Loupe HUD updates; supports toggle [Auto-Magnify ON/OFF] and manual zoom presets (Fit / 185% / 225%) | H118: Passed | I118: Verified by Automated Unit Tests (AUT-FRONT-99)
A119: SA-STU-52 | B119: SA 2025 RO Studio | C119: Tier 2 (Workflow & Ergonomics) | D119: 2025 RO Excel Studio (All Sheets) | E119: Service Advisor | F119: Senior SA 5-Second Timed Auto-Magnifier Rule & Stutter-Free Typing Debounce | G119: When SA types into any field preview instantly magnifies wider directly on the field with immediate live text reflection in Loupe HUD; suppresses mid-typing PDF iframe reload restarts by holding 5000ms debounce; automatically glides back to normal view (Fit 100%) after 5 seconds of inactivity | H119: Passed | I119: Verified by Automated Unit Tests (AUT-FRONT-99)
A120: SA-STU-53 | B120: SA 2025 RO Studio | C120: Tier 2 (Workflow & Ergonomics) | D120: 2025 RO Excel Studio (All Sheets) | E120: Service Advisor | F120: Pure Follow-Along Auto-Magnifier & Clean Document Real-Time Typing Sync | G120: When SA focuses or types into form inputs right-side PDF preview smoothly glides and magnifies onto the active document zone (Customer Details Scope Claim Stub Diagnostics) and stays locked on it without any 5-second auto-reset timer; floating black Loupe HUD badge is permanently suppressed across all 4 sheet views keeping preview 100% clean and unobstructed; PDF debounces smoothly to reflect typed data directly on the document | H120: Passed | I120: Verified by Automated Unit Tests (AUT-FRONT-99)
A121: SA-STU-54 | B121: SA 2025 RO Studio | C121: Tier 1 (Core Reliability & Data Integrity) | D121: 2025 RO Excel Studio (All Sheets) | E121: Service Advisor | F121: 100% Crisp Vector Resolution & Blurriness-Free Live Typing Reflection | G121: Defaults Auto-Magnify to OFF across all 4 sheet views so document preview maintains 100% sharp native vector resolution (scale 1.0) without GPU pixel-stretching, jumping, or blurriness; typing smoothly updates full document in real time without lag | H121: Passed | I121: Verified by Automated Unit Tests (AUT-FRONT-99)
A122: SA-STU-55 | B122: SA 2025 RO Studio | C122: Tier 1 (Core Reliability & Data Integrity) | D122: 2025 RO Excel Studio (All Sheets) | E122: Service Advisor | F122: Solution A High-Definition Field Inspector Loupe HUD & Zero-Blur Vector Resolution | G122: When SA enables Auto-Magnify or focuses/types into any form field a sleek high-definition Loupe Inspector HUD displays the field badge and typed text in real time with 0ms lag and high-contrast typography; the PDF iframe remains fixed at 100% native vector scale (1.0) completely eliminating CSS pixel stretching blurriness and reload jitter; includes instant dismissal toggle and cross-sheet synchronization | H122: Passed | I122: Verified by Automated Unit Tests (AUT-FRONT-99) and Headless Browser Verification
A123: SA-STU-56 | B123: SA 2025 RO Studio | C123: Tier 2 (Workflow & Ergonomics) | D123: 2025 RO Excel Studio (All Sheets) | E123: Service Advisor | F123: Senior Follow-Along Document Auto-Magnify with Natural Glide-Back & Crisp Contrast Resolution | G123: When non-techy senior SA types or focuses into any form field the PDF preview automatically and smoothly glides to center on that exact document section with crisp vector contrast; the inserted text appears live directly on the PDF without dark HUD obstruction; after 3.5s of typing inactivity or upon field blur the view smoothly and naturally glides back to 100% Fit view | H123: Passed | I123: Verified by Automated Unit Tests (AUT-FRONT-100) and Browser Verification
A124: SA-STU-57 | B124: SA 2025 RO Studio | C124: Tier 1 (Core Reliability & Data Integrity) | D124: 2025 RO Excel Studio (All Sheets) | E124: Service Advisor | F124: Option 1 High-Definition Super-Sampling (200% Layout & 0.5 Base Downsample) for Senior SA Studio with Razor-Sharp Crisp Zoom | G124: PDF preview iframes across all 4 sheets are wrapped in high-definition super-sampling viewports with 200% width/height rendering the PDF natively at ~950px+ resolution; standard view scales down by 0.5 to perfectly fit the viewport container with retina-quality sharpness; follow-along auto-zoom scales to 0.88-0.95 remaining within native vector resolution with zero pixel stretching or blurriness; natural 3.5s inactivity glide-back returns smoothly to 0.5 fit view | H124: Passed | I124: Verified by Automated Unit Tests (AUT-FRONT-101) and Headless Browser DevTools
A125: SA-STU-58 | B125: SA 2025 RO Studio | C125: Tier 1 (Core Reliability & Data Integrity) | D125: 2025 RO Excel Studio (All Sheets) | E125: Service Advisor | F125: Full-Form Dynamic Follow-Along Auto-Magnifier with Mathematical Camera Centering Across Middle Tables Signatures and Bottom Claim Stub | G125: When SA focuses or types into any input across all 4 worksheets (Job Order Quotation Billing Checklist) including header dispatch customer dossier diagnostic scope middle parts and materials tables quotation/billing line items calculation totals signatures (SA Mechanic Assessor GM) bottom claim stub and checklist multi-point categories the PDF preview mathematically calculates the exact viewport translation to smoothly glide and center right on that section of the document with retina sharpness (scale 0.88); dynamic table rows automatically delegate focus to the corresponding table area; 3.5s inactivity or blur smoothly glides back naturally to 0.5 fit view | H125: Passed | I125: Verified by Automated Unit Tests (AUT-FRONT-102)
A126: SA-STU-59 | B126: SA 2025 RO Studio | C126: Tier 1 (Core Reliability & Data Integrity) | D126: 2025 RO Excel Studio (All Sheets) | E126: Service Advisor | F126: Hardcoded Section-Lock Navigation Permanent Document Lock & 1-Click Quick-Lock Navigation Pills | G126: When SA clicks or focuses into any input or table section the PDF preview mathematically snaps to that calibrated vertical ratio (0.0 for Customer 0.25 for Diagnostics 0.50 for Parts Table 0.85 for Signatures 1.00 for Claim Stub) and stays permanently locked without jumping back after 3.5s; includes 1-click Quick Lock navigation pills ([Fit] [Customer] [Scope] [Parts Table] [Signatures] [Claim Stub]) right above the PDF viewer across all 4 sheet views; [Fit] button immediately returns to full document view (scale 0.5) | H126: Passed | I126: Verified by Automated Unit Tests (AUT-FRONT-103)
... A141: SA-17 | B141: Service Advisor | C141: Tier 2 (Workflow & Ergonomics) | D141: 2025 RO Studio Decommission Auto-Magnifier & Steady PDF Preview | E141: Service Advisor | F141: Open RO Studio across all 4 worksheets and type into form fields | G141: Auto-magnifier toggle and manual zoom presets are removed from toolbar; typing or focusing on form fields does not trigger camera zoom or panning jumps; PDF iframe maintains a rock-steady 100% aspect fit; PDF updates smoothly without viewport jitter | H141: Passed | I141: Verified by Automated Unit Tests (tests/frontend/sla_and_logic.test.js) and manual UI inspection
A142: AST-62 | B142: Assistant Staff | C142: Tier 1 (Core Business Flow) | D142: Online Booking Branch Dispatch | E142: Assistant | F142: Log in as Assistant, open Online Booking Form, choose Target Branch = Regalado Branch, fill customer/plate/model and submit | G142: Toast reads 'Vehicle <PLATE> registered to Regalado Branch Booking Module.' (Booking Dispatched); view switches to the Booking Module filtered to Regalado Branch; new booking row shows the customer name and contact; top-right badge reads 'Regalado Branch · Online Queue'; no Branch column in the table | H142: Pending
A143: SA-18 | B143: Service Advisor | C143: Tier 1 (Security & Data Isolation) | D143: SA Branch-Locked Online Bookings | E143: Service Advisor | F143: With a Regalado booking pending, log in as Marikina SA (sa@hontech.com) and click Online Bookings; then log in as Regalado SA (sa.east@hontech.com) and click Online Bookings | G143: Marikina SA does not see the Regalado booking and has no branch switcher; Regalado SA sees it; only the Booking Module card is shown; top-right badge is static plain text '<Branch> · Online Queue' with no emoji and no blinking/pulsing dot; table has no Branch column | H143: Pending
A144: SA-19 | B144: Service Advisor | C144: Tier 1 (Core Business Flow) | D144: Load to 2025 RO Studio Handover | E144: Service Advisor | F144: As Regalado SA in Online Bookings click [Load to RO Studio] on the pending booking, complete inspection fields, then click [Register Repair Order to System] | G144: Studio opens on Form 1/3 prefilled with name, contact, plate, model, concern, intake date, category and Job No = booking ID; after Register the booking disappears from Online Bookings, appears once (no duplicate) in Daily Intakes as Waiting with a claim stub; toast 'Booking Handover Complete' | H144: Pending
A145: SA-20 | B145: Service Advisor | C145: Tier 2 (Workflow & Ergonomics) | D145: SA Navigation & Daily Intakes Online Module Consolidation | E145: Service Advisor | F145: Log in as Service Advisor (sa@hontech.com), inspect left sidebar and top navbar, then click Daily Intakes | G145: Sidebar and header navigation contain strictly 5 tools (2025 RO Excel Studio, Daily Intakes, Customer Lookup, Bay Status, TV Monitor) with no separate Online Bookings button; clicking Daily Intakes displays the branch-isolated Online Booking Module at the head with active workshop queue below; table has no Branch column and features a clean static top-right badge | H145: Passed | I145: Verified by Automated Unit Tests (tests/frontend/app.test.js AUT-FRONT-108 and AUT-FRONT-113)
A146: AUTH-30 | B146: Authentication | C146: Tier 2 (Workflow & Ergonomics) | D146: Official System Title Branding | E146: All Roles | F146: Open the login page (frontend/index.html) in any browser | G146: Browser tab title displays 'HonTech — Web-Based Operations and Real-Time Queue Management System' and left hero header displays 'Web-Based Operations and Real-Time Queue Management System' with styled red accent on 'Management System' | H146: Passed | I146: Verified by Automated Unit Tests (tests/frontend/app.test.js AUT-FRONT-114)
A147: SA-21 | B147: Service Advisor | C147: Tier 2 (Workflow & Ergonomics) | D147: 2025 RO Excel Studio PDF Document Formatting & Coordinate Precision | E147: Service Advisor | F147: Open 2025 RO Excel Studio, populate Customer and Vehicle details (including long vehicle model), inspect live PDF preview and Fullscreen Enlarge Modal across Form 1/3, Quotation, Billing, and Checklist | G147: Text sits cleanly +1.3pt above pre-printed underlines without horizontal lines slicing through letters; Job Order No sits centered on underline (Y=781.5) and Date sits centered inside date box (Y=758.2); Plate No and Job/Quote/Billing No display in bold; Concern Box text starts inside margins (X=94, Y=652) with no border collision; long values auto-shrink down to 5.2pt without clipping or crashing into adjacent columns | H147: Passed | I147: Verified by Automated Unit Tests (tests/frontend/sla_and_logic.test.js AUT-FRONT-94 and AUT-FRONT-106)
...
